const x = 10;

try {
    x = 1;
} catch (error) {
    console.log('Ocorreu um erro:', error)
}

console.log('continuando o codigo...');